HTTPSConnectionPool(host='www.bbcgoodfood.com', port=443): Max retries exceeded with url: /recipes/chicken-creamy-bacon-penne (Caused by NameResolutionError("<urllib3.connection.HTTPSConnection object at 0x7f5e7b53acb0>: Failed to resolve 'www.bbcgoodfood.com' ([Errno -3] Temporary failure in name resolution)"))
Traceback (most recent call last):
  File "/home/jose/Downloads/3 POC/2 telegram_chatbot/code_repo/venv/lib/python3.10/site-packages/urllib3/connection.py", line 198, in _new_conn
    sock = connection.create_connection(
  File "/home/jose/Downloads/3 POC/2 telegram_chatbot/code_repo/venv/lib/python3.10/site-packages/urllib3/util/connection.py", line 60, in create_connection
    for res in socket.getaddrinfo(host, port, family, socket.SOCK_STREAM):
  File "/usr/lib/python3.10/socket.py", line 955, in getaddrinfo
    for res in _socket.getaddrinfo(host, port, family, type, proto, flags):
socket.gaierror: [Errno -3] Temporary failure in name resolution

The above exception was the direct cause of the following exception:

Traceback (most recent call last):
  File "/home/jose/Downloads/3 POC/2 telegram_chatbot/code_repo/venv/lib/python3.10/site-packages/urllib3/connectionpool.py", line 793, in urlopen
    response = self._make_request(
  File "/home/jose/Downloads/3 POC/2 telegram_chatbot/code_repo/venv/lib/python3.10/site-packages/urllib3/connectionpool.py", line 491, in _make_request
    raise new_e
  File "/home/jose/Downloads/3 POC/2 telegram_chatbot/code_repo/venv/lib/python3.10/site-packages/urllib3/connectionpool.py", line 467, in _make_request
    self._validate_conn(conn)
  File "/home/jose/Downloads/3 POC/2 telegram_chatbot/code_repo/venv/lib/python3.10/site-packages/urllib3/connectionpool.py", line 1099, in _validate_conn
    conn.connect()
  File "/home/jose/Downloads/3 POC/2 telegram_chatbot/code_repo/venv/lib/python3.10/site-packages/urllib3/connection.py", line 616, in connect
    self.sock = sock = self._new_conn()
  File "/home/jose/Downloads/3 POC/2 telegram_chatbot/code_repo/venv/lib/python3.10/site-packages/urllib3/connection.py", line 205, in _new_conn
    raise NameResolutionError(self.host, self, e) from e
urllib3.exceptions.NameResolutionError: <urllib3.connection.HTTPSConnection object at 0x7f5e7b53acb0>: Failed to resolve 'www.bbcgoodfood.com' ([Errno -3] Temporary failure in name resolution)

The above exception was the direct cause of the following exception:

Traceback (most recent call last):
  File "/home/jose/Downloads/3 POC/2 telegram_chatbot/code_repo/venv/lib/python3.10/site-packages/requests/adapters.py", line 486, in send
    resp = conn.urlopen(
  File "/home/jose/Downloads/3 POC/2 telegram_chatbot/code_repo/venv/lib/python3.10/site-packages/urllib3/connectionpool.py", line 847, in urlopen
    retries = retries.increment(
  File "/home/jose/Downloads/3 POC/2 telegram_chatbot/code_repo/venv/lib/python3.10/site-packages/urllib3/util/retry.py", line 515, in increment
    raise MaxRetryError(_pool, url, reason) from reason  # type: ignore[arg-type]
urllib3.exceptions.MaxRetryError: HTTPSConnectionPool(host='www.bbcgoodfood.com', port=443): Max retries exceeded with url: /recipes/chicken-creamy-bacon-penne (Caused by NameResolutionError("<urllib3.connection.HTTPSConnection object at 0x7f5e7b53acb0>: Failed to resolve 'www.bbcgoodfood.com' ([Errno -3] Temporary failure in name resolution)"))

During handling of the above exception, another exception occurred:

Traceback (most recent call last):
  File "/home/jose/Downloads/3 POC/2 telegram_chatbot/code_repo/bot/webscraper.py", line 109, in <module>
    raise e
  File "/home/jose/Downloads/3 POC/2 telegram_chatbot/code_repo/bot/webscraper.py", line 98, in <module>
    link_scraper(url, redis_conn, mongo)
  File "/home/jose/Downloads/3 POC/2 telegram_chatbot/code_repo/bot/webscraper.py", line 66, in link_scraper
    recipe_scraper(link, hash, redis_conn, mongo, page_number)
  File "/home/jose/Downloads/3 POC/2 telegram_chatbot/code_repo/bot/webscraper.py", line 24, in recipe_scraper
    page = requests.get(recipe_url)
  File "/home/jose/Downloads/3 POC/2 telegram_chatbot/code_repo/venv/lib/python3.10/site-packages/requests/api.py", line 73, in get
    return request("get", url, params=params, **kwargs)
  File "/home/jose/Downloads/3 POC/2 telegram_chatbot/code_repo/venv/lib/python3.10/site-packages/requests/api.py", line 59, in request
    return session.request(method=method, url=url, **kwargs)
  File "/home/jose/Downloads/3 POC/2 telegram_chatbot/code_repo/venv/lib/python3.10/site-packages/requests/sessions.py", line 589, in request
    resp = self.send(prep, **send_kwargs)
  File "/home/jose/Downloads/3 POC/2 telegram_chatbot/code_repo/venv/lib/python3.10/site-packages/requests/sessions.py", line 703, in send
    r = adapter.send(request, **kwargs)
  File "/home/jose/Downloads/3 POC/2 telegram_chatbot/code_repo/venv/lib/python3.10/site-packages/requests/adapters.py", line 519, in send
    raise ConnectionError(e, request=request)
requests.exceptions.ConnectionError: HTTPSConnectionPool(host='www.bbcgoodfood.com', port=443): Max retries exceeded with url: /recipes/chicken-creamy-bacon-penne (Caused by NameResolutionError("<urllib3.connection.HTTPSConnection object at 0x7f5e7b53acb0>: Failed to resolve 'www.bbcgoodfood.com' ([Errno -3] Temporary failure in name resolution)"))
